{
 "cells": [
  {
   "cell_type": "markdown",
   "id": "5ac8f793-5fed-4646-8d68-9ebfc5e4c67c",
   "metadata": {},
   "source": [
    "# Voila test"
   ]
  },
  {
   "cell_type": "code",
   "execution_count": null,
   "id": "b84635f2-377a-4cf1-9005-cd8f37e3ea65",
   "metadata": {},
   "outputs": [],
   "source": [
    "from dash import jupyter_dash\n",
    "jupyter_dash.infer_jupyter_proxy_config()"
   ]
  },
  {
   "cell_type": "code",
   "execution_count": 1,
   "id": "057219d0-fe3c-4c08-b101-8b7f72e437f9",
   "metadata": {},
   "outputs": [
    {
     "ename": "ConnectionError",
     "evalue": "HTTPConnectionPool(host='0.0.0.0', port=8080): Max retries exceeded with url: /_alive_b3236f93-da64-4976-ba8e-a9c286fec5c6 (Caused by NewConnectionError('<urllib3.connection.HTTPConnection object at 0x000001BC5B4EAC40>: Failed to establish a new connection: [WinError 10049] Die angeforderte Adresse ist in diesem Kontext ungültig'))",
     "output_type": "error",
     "traceback": [
      "\u001b[1;31m---------------------------------------------------------------------------\u001b[0m",
      "\u001b[1;31mOSError\u001b[0m                                   Traceback (most recent call last)",
      "File \u001b[1;32m~\\Anaconda3\\lib\\site-packages\\urllib3\\connection.py:174\u001b[0m, in \u001b[0;36mHTTPConnection._new_conn\u001b[1;34m(self)\u001b[0m\n\u001b[0;32m    173\u001b[0m \u001b[38;5;28;01mtry\u001b[39;00m:\n\u001b[1;32m--> 174\u001b[0m     conn \u001b[38;5;241m=\u001b[39m connection\u001b[38;5;241m.\u001b[39mcreate_connection(\n\u001b[0;32m    175\u001b[0m         (\u001b[38;5;28mself\u001b[39m\u001b[38;5;241m.\u001b[39m_dns_host, \u001b[38;5;28mself\u001b[39m\u001b[38;5;241m.\u001b[39mport), \u001b[38;5;28mself\u001b[39m\u001b[38;5;241m.\u001b[39mtimeout, \u001b[38;5;241m*\u001b[39m\u001b[38;5;241m*\u001b[39mextra_kw\n\u001b[0;32m    176\u001b[0m     )\n\u001b[0;32m    178\u001b[0m \u001b[38;5;28;01mexcept\u001b[39;00m SocketTimeout:\n",
      "File \u001b[1;32m~\\Anaconda3\\lib\\site-packages\\urllib3\\util\\connection.py:95\u001b[0m, in \u001b[0;36mcreate_connection\u001b[1;34m(address, timeout, source_address, socket_options)\u001b[0m\n\u001b[0;32m     94\u001b[0m \u001b[38;5;28;01mif\u001b[39;00m err \u001b[38;5;129;01mis\u001b[39;00m \u001b[38;5;129;01mnot\u001b[39;00m \u001b[38;5;28;01mNone\u001b[39;00m:\n\u001b[1;32m---> 95\u001b[0m     \u001b[38;5;28;01mraise\u001b[39;00m err\n\u001b[0;32m     97\u001b[0m \u001b[38;5;28;01mraise\u001b[39;00m socket\u001b[38;5;241m.\u001b[39merror(\u001b[38;5;124m\"\u001b[39m\u001b[38;5;124mgetaddrinfo returns an empty list\u001b[39m\u001b[38;5;124m\"\u001b[39m)\n",
      "File \u001b[1;32m~\\Anaconda3\\lib\\site-packages\\urllib3\\util\\connection.py:85\u001b[0m, in \u001b[0;36mcreate_connection\u001b[1;34m(address, timeout, source_address, socket_options)\u001b[0m\n\u001b[0;32m     84\u001b[0m     sock\u001b[38;5;241m.\u001b[39mbind(source_address)\n\u001b[1;32m---> 85\u001b[0m \u001b[43msock\u001b[49m\u001b[38;5;241;43m.\u001b[39;49m\u001b[43mconnect\u001b[49m\u001b[43m(\u001b[49m\u001b[43msa\u001b[49m\u001b[43m)\u001b[49m\n\u001b[0;32m     86\u001b[0m \u001b[38;5;28;01mreturn\u001b[39;00m sock\n",
      "\u001b[1;31mOSError\u001b[0m: [WinError 10049] Die angeforderte Adresse ist in diesem Kontext ungültig",
      "\nDuring handling of the above exception, another exception occurred:\n",
      "\u001b[1;31mNewConnectionError\u001b[0m                        Traceback (most recent call last)",
      "File \u001b[1;32m~\\Anaconda3\\lib\\site-packages\\urllib3\\connectionpool.py:715\u001b[0m, in \u001b[0;36mHTTPConnectionPool.urlopen\u001b[1;34m(self, method, url, body, headers, retries, redirect, assert_same_host, timeout, pool_timeout, release_conn, chunked, body_pos, **response_kw)\u001b[0m\n\u001b[0;32m    714\u001b[0m \u001b[38;5;66;03m# Make the request on the httplib connection object.\u001b[39;00m\n\u001b[1;32m--> 715\u001b[0m httplib_response \u001b[38;5;241m=\u001b[39m \u001b[38;5;28;43mself\u001b[39;49m\u001b[38;5;241;43m.\u001b[39;49m\u001b[43m_make_request\u001b[49m\u001b[43m(\u001b[49m\n\u001b[0;32m    716\u001b[0m \u001b[43m    \u001b[49m\u001b[43mconn\u001b[49m\u001b[43m,\u001b[49m\n\u001b[0;32m    717\u001b[0m \u001b[43m    \u001b[49m\u001b[43mmethod\u001b[49m\u001b[43m,\u001b[49m\n\u001b[0;32m    718\u001b[0m \u001b[43m    \u001b[49m\u001b[43murl\u001b[49m\u001b[43m,\u001b[49m\n\u001b[0;32m    719\u001b[0m \u001b[43m    \u001b[49m\u001b[43mtimeout\u001b[49m\u001b[38;5;241;43m=\u001b[39;49m\u001b[43mtimeout_obj\u001b[49m\u001b[43m,\u001b[49m\n\u001b[0;32m    720\u001b[0m \u001b[43m    \u001b[49m\u001b[43mbody\u001b[49m\u001b[38;5;241;43m=\u001b[39;49m\u001b[43mbody\u001b[49m\u001b[43m,\u001b[49m\n\u001b[0;32m    721\u001b[0m \u001b[43m    \u001b[49m\u001b[43mheaders\u001b[49m\u001b[38;5;241;43m=\u001b[39;49m\u001b[43mheaders\u001b[49m\u001b[43m,\u001b[49m\n\u001b[0;32m    722\u001b[0m \u001b[43m    \u001b[49m\u001b[43mchunked\u001b[49m\u001b[38;5;241;43m=\u001b[39;49m\u001b[43mchunked\u001b[49m\u001b[43m,\u001b[49m\n\u001b[0;32m    723\u001b[0m \u001b[43m\u001b[49m\u001b[43m)\u001b[49m\n\u001b[0;32m    725\u001b[0m \u001b[38;5;66;03m# If we're going to release the connection in ``finally:``, then\u001b[39;00m\n\u001b[0;32m    726\u001b[0m \u001b[38;5;66;03m# the response doesn't need to know about the connection. Otherwise\u001b[39;00m\n\u001b[0;32m    727\u001b[0m \u001b[38;5;66;03m# it will also try to release it and we'll have a double-release\u001b[39;00m\n\u001b[0;32m    728\u001b[0m \u001b[38;5;66;03m# mess.\u001b[39;00m\n",
      "File \u001b[1;32m~\\Anaconda3\\lib\\site-packages\\urllib3\\connectionpool.py:416\u001b[0m, in \u001b[0;36mHTTPConnectionPool._make_request\u001b[1;34m(self, conn, method, url, timeout, chunked, **httplib_request_kw)\u001b[0m\n\u001b[0;32m    415\u001b[0m     \u001b[38;5;28;01melse\u001b[39;00m:\n\u001b[1;32m--> 416\u001b[0m         conn\u001b[38;5;241m.\u001b[39mrequest(method, url, \u001b[38;5;241m*\u001b[39m\u001b[38;5;241m*\u001b[39mhttplib_request_kw)\n\u001b[0;32m    418\u001b[0m \u001b[38;5;66;03m# We are swallowing BrokenPipeError (errno.EPIPE) since the server is\u001b[39;00m\n\u001b[0;32m    419\u001b[0m \u001b[38;5;66;03m# legitimately able to close the connection after sending a valid response.\u001b[39;00m\n\u001b[0;32m    420\u001b[0m \u001b[38;5;66;03m# With this behaviour, the received response is still readable.\u001b[39;00m\n",
      "File \u001b[1;32m~\\Anaconda3\\lib\\site-packages\\urllib3\\connection.py:244\u001b[0m, in \u001b[0;36mHTTPConnection.request\u001b[1;34m(self, method, url, body, headers)\u001b[0m\n\u001b[0;32m    243\u001b[0m     headers[\u001b[38;5;124m\"\u001b[39m\u001b[38;5;124mUser-Agent\u001b[39m\u001b[38;5;124m\"\u001b[39m] \u001b[38;5;241m=\u001b[39m _get_default_user_agent()\n\u001b[1;32m--> 244\u001b[0m \u001b[38;5;28;43msuper\u001b[39;49m\u001b[43m(\u001b[49m\u001b[43mHTTPConnection\u001b[49m\u001b[43m,\u001b[49m\u001b[43m \u001b[49m\u001b[38;5;28;43mself\u001b[39;49m\u001b[43m)\u001b[49m\u001b[38;5;241;43m.\u001b[39;49m\u001b[43mrequest\u001b[49m\u001b[43m(\u001b[49m\u001b[43mmethod\u001b[49m\u001b[43m,\u001b[49m\u001b[43m \u001b[49m\u001b[43murl\u001b[49m\u001b[43m,\u001b[49m\u001b[43m \u001b[49m\u001b[43mbody\u001b[49m\u001b[38;5;241;43m=\u001b[39;49m\u001b[43mbody\u001b[49m\u001b[43m,\u001b[49m\u001b[43m \u001b[49m\u001b[43mheaders\u001b[49m\u001b[38;5;241;43m=\u001b[39;49m\u001b[43mheaders\u001b[49m\u001b[43m)\u001b[49m\n",
      "File \u001b[1;32m~\\Anaconda3\\lib\\http\\client.py:1285\u001b[0m, in \u001b[0;36mHTTPConnection.request\u001b[1;34m(self, method, url, body, headers, encode_chunked)\u001b[0m\n\u001b[0;32m   1284\u001b[0m \u001b[38;5;250m\u001b[39m\u001b[38;5;124;03m\"\"\"Send a complete request to the server.\"\"\"\u001b[39;00m\n\u001b[1;32m-> 1285\u001b[0m \u001b[38;5;28;43mself\u001b[39;49m\u001b[38;5;241;43m.\u001b[39;49m\u001b[43m_send_request\u001b[49m\u001b[43m(\u001b[49m\u001b[43mmethod\u001b[49m\u001b[43m,\u001b[49m\u001b[43m \u001b[49m\u001b[43murl\u001b[49m\u001b[43m,\u001b[49m\u001b[43m \u001b[49m\u001b[43mbody\u001b[49m\u001b[43m,\u001b[49m\u001b[43m \u001b[49m\u001b[43mheaders\u001b[49m\u001b[43m,\u001b[49m\u001b[43m \u001b[49m\u001b[43mencode_chunked\u001b[49m\u001b[43m)\u001b[49m\n",
      "File \u001b[1;32m~\\Anaconda3\\lib\\http\\client.py:1331\u001b[0m, in \u001b[0;36mHTTPConnection._send_request\u001b[1;34m(self, method, url, body, headers, encode_chunked)\u001b[0m\n\u001b[0;32m   1330\u001b[0m     body \u001b[38;5;241m=\u001b[39m _encode(body, \u001b[38;5;124m'\u001b[39m\u001b[38;5;124mbody\u001b[39m\u001b[38;5;124m'\u001b[39m)\n\u001b[1;32m-> 1331\u001b[0m \u001b[38;5;28;43mself\u001b[39;49m\u001b[38;5;241;43m.\u001b[39;49m\u001b[43mendheaders\u001b[49m\u001b[43m(\u001b[49m\u001b[43mbody\u001b[49m\u001b[43m,\u001b[49m\u001b[43m \u001b[49m\u001b[43mencode_chunked\u001b[49m\u001b[38;5;241;43m=\u001b[39;49m\u001b[43mencode_chunked\u001b[49m\u001b[43m)\u001b[49m\n",
      "File \u001b[1;32m~\\Anaconda3\\lib\\http\\client.py:1280\u001b[0m, in \u001b[0;36mHTTPConnection.endheaders\u001b[1;34m(self, message_body, encode_chunked)\u001b[0m\n\u001b[0;32m   1279\u001b[0m     \u001b[38;5;28;01mraise\u001b[39;00m CannotSendHeader()\n\u001b[1;32m-> 1280\u001b[0m \u001b[38;5;28;43mself\u001b[39;49m\u001b[38;5;241;43m.\u001b[39;49m\u001b[43m_send_output\u001b[49m\u001b[43m(\u001b[49m\u001b[43mmessage_body\u001b[49m\u001b[43m,\u001b[49m\u001b[43m \u001b[49m\u001b[43mencode_chunked\u001b[49m\u001b[38;5;241;43m=\u001b[39;49m\u001b[43mencode_chunked\u001b[49m\u001b[43m)\u001b[49m\n",
      "File \u001b[1;32m~\\Anaconda3\\lib\\http\\client.py:1040\u001b[0m, in \u001b[0;36mHTTPConnection._send_output\u001b[1;34m(self, message_body, encode_chunked)\u001b[0m\n\u001b[0;32m   1039\u001b[0m \u001b[38;5;28;01mdel\u001b[39;00m \u001b[38;5;28mself\u001b[39m\u001b[38;5;241m.\u001b[39m_buffer[:]\n\u001b[1;32m-> 1040\u001b[0m \u001b[38;5;28;43mself\u001b[39;49m\u001b[38;5;241;43m.\u001b[39;49m\u001b[43msend\u001b[49m\u001b[43m(\u001b[49m\u001b[43mmsg\u001b[49m\u001b[43m)\u001b[49m\n\u001b[0;32m   1042\u001b[0m \u001b[38;5;28;01mif\u001b[39;00m message_body \u001b[38;5;129;01mis\u001b[39;00m \u001b[38;5;129;01mnot\u001b[39;00m \u001b[38;5;28;01mNone\u001b[39;00m:\n\u001b[0;32m   1043\u001b[0m \n\u001b[0;32m   1044\u001b[0m     \u001b[38;5;66;03m# create a consistent interface to message_body\u001b[39;00m\n",
      "File \u001b[1;32m~\\Anaconda3\\lib\\http\\client.py:980\u001b[0m, in \u001b[0;36mHTTPConnection.send\u001b[1;34m(self, data)\u001b[0m\n\u001b[0;32m    979\u001b[0m \u001b[38;5;28;01mif\u001b[39;00m \u001b[38;5;28mself\u001b[39m\u001b[38;5;241m.\u001b[39mauto_open:\n\u001b[1;32m--> 980\u001b[0m     \u001b[38;5;28;43mself\u001b[39;49m\u001b[38;5;241;43m.\u001b[39;49m\u001b[43mconnect\u001b[49m\u001b[43m(\u001b[49m\u001b[43m)\u001b[49m\n\u001b[0;32m    981\u001b[0m \u001b[38;5;28;01melse\u001b[39;00m:\n",
      "File \u001b[1;32m~\\Anaconda3\\lib\\site-packages\\urllib3\\connection.py:205\u001b[0m, in \u001b[0;36mHTTPConnection.connect\u001b[1;34m(self)\u001b[0m\n\u001b[0;32m    204\u001b[0m \u001b[38;5;28;01mdef\u001b[39;00m \u001b[38;5;21mconnect\u001b[39m(\u001b[38;5;28mself\u001b[39m):\n\u001b[1;32m--> 205\u001b[0m     conn \u001b[38;5;241m=\u001b[39m \u001b[38;5;28;43mself\u001b[39;49m\u001b[38;5;241;43m.\u001b[39;49m\u001b[43m_new_conn\u001b[49m\u001b[43m(\u001b[49m\u001b[43m)\u001b[49m\n\u001b[0;32m    206\u001b[0m     \u001b[38;5;28mself\u001b[39m\u001b[38;5;241m.\u001b[39m_prepare_conn(conn)\n",
      "File \u001b[1;32m~\\Anaconda3\\lib\\site-packages\\urllib3\\connection.py:186\u001b[0m, in \u001b[0;36mHTTPConnection._new_conn\u001b[1;34m(self)\u001b[0m\n\u001b[0;32m    185\u001b[0m \u001b[38;5;28;01mexcept\u001b[39;00m SocketError \u001b[38;5;28;01mas\u001b[39;00m e:\n\u001b[1;32m--> 186\u001b[0m     \u001b[38;5;28;01mraise\u001b[39;00m NewConnectionError(\n\u001b[0;32m    187\u001b[0m         \u001b[38;5;28mself\u001b[39m, \u001b[38;5;124m\"\u001b[39m\u001b[38;5;124mFailed to establish a new connection: \u001b[39m\u001b[38;5;132;01m%s\u001b[39;00m\u001b[38;5;124m\"\u001b[39m \u001b[38;5;241m%\u001b[39m e\n\u001b[0;32m    188\u001b[0m     )\n\u001b[0;32m    190\u001b[0m \u001b[38;5;28;01mreturn\u001b[39;00m conn\n",
      "\u001b[1;31mNewConnectionError\u001b[0m: <urllib3.connection.HTTPConnection object at 0x000001BC5B4EAC40>: Failed to establish a new connection: [WinError 10049] Die angeforderte Adresse ist in diesem Kontext ungültig",
      "\nDuring handling of the above exception, another exception occurred:\n",
      "\u001b[1;31mMaxRetryError\u001b[0m                             Traceback (most recent call last)",
      "File \u001b[1;32m~\\Anaconda3\\lib\\site-packages\\requests\\adapters.py:486\u001b[0m, in \u001b[0;36mHTTPAdapter.send\u001b[1;34m(self, request, stream, timeout, verify, cert, proxies)\u001b[0m\n\u001b[0;32m    485\u001b[0m \u001b[38;5;28;01mtry\u001b[39;00m:\n\u001b[1;32m--> 486\u001b[0m     resp \u001b[38;5;241m=\u001b[39m \u001b[43mconn\u001b[49m\u001b[38;5;241;43m.\u001b[39;49m\u001b[43murlopen\u001b[49m\u001b[43m(\u001b[49m\n\u001b[0;32m    487\u001b[0m \u001b[43m        \u001b[49m\u001b[43mmethod\u001b[49m\u001b[38;5;241;43m=\u001b[39;49m\u001b[43mrequest\u001b[49m\u001b[38;5;241;43m.\u001b[39;49m\u001b[43mmethod\u001b[49m\u001b[43m,\u001b[49m\n\u001b[0;32m    488\u001b[0m \u001b[43m        \u001b[49m\u001b[43murl\u001b[49m\u001b[38;5;241;43m=\u001b[39;49m\u001b[43murl\u001b[49m\u001b[43m,\u001b[49m\n\u001b[0;32m    489\u001b[0m \u001b[43m        \u001b[49m\u001b[43mbody\u001b[49m\u001b[38;5;241;43m=\u001b[39;49m\u001b[43mrequest\u001b[49m\u001b[38;5;241;43m.\u001b[39;49m\u001b[43mbody\u001b[49m\u001b[43m,\u001b[49m\n\u001b[0;32m    490\u001b[0m \u001b[43m        \u001b[49m\u001b[43mheaders\u001b[49m\u001b[38;5;241;43m=\u001b[39;49m\u001b[43mrequest\u001b[49m\u001b[38;5;241;43m.\u001b[39;49m\u001b[43mheaders\u001b[49m\u001b[43m,\u001b[49m\n\u001b[0;32m    491\u001b[0m \u001b[43m        \u001b[49m\u001b[43mredirect\u001b[49m\u001b[38;5;241;43m=\u001b[39;49m\u001b[38;5;28;43;01mFalse\u001b[39;49;00m\u001b[43m,\u001b[49m\n\u001b[0;32m    492\u001b[0m \u001b[43m        \u001b[49m\u001b[43massert_same_host\u001b[49m\u001b[38;5;241;43m=\u001b[39;49m\u001b[38;5;28;43;01mFalse\u001b[39;49;00m\u001b[43m,\u001b[49m\n\u001b[0;32m    493\u001b[0m \u001b[43m        \u001b[49m\u001b[43mpreload_content\u001b[49m\u001b[38;5;241;43m=\u001b[39;49m\u001b[38;5;28;43;01mFalse\u001b[39;49;00m\u001b[43m,\u001b[49m\n\u001b[0;32m    494\u001b[0m \u001b[43m        \u001b[49m\u001b[43mdecode_content\u001b[49m\u001b[38;5;241;43m=\u001b[39;49m\u001b[38;5;28;43;01mFalse\u001b[39;49;00m\u001b[43m,\u001b[49m\n\u001b[0;32m    495\u001b[0m \u001b[43m        \u001b[49m\u001b[43mretries\u001b[49m\u001b[38;5;241;43m=\u001b[39;49m\u001b[38;5;28;43mself\u001b[39;49m\u001b[38;5;241;43m.\u001b[39;49m\u001b[43mmax_retries\u001b[49m\u001b[43m,\u001b[49m\n\u001b[0;32m    496\u001b[0m \u001b[43m        \u001b[49m\u001b[43mtimeout\u001b[49m\u001b[38;5;241;43m=\u001b[39;49m\u001b[43mtimeout\u001b[49m\u001b[43m,\u001b[49m\n\u001b[0;32m    497\u001b[0m \u001b[43m        \u001b[49m\u001b[43mchunked\u001b[49m\u001b[38;5;241;43m=\u001b[39;49m\u001b[43mchunked\u001b[49m\u001b[43m,\u001b[49m\n\u001b[0;32m    498\u001b[0m \u001b[43m    \u001b[49m\u001b[43m)\u001b[49m\n\u001b[0;32m    500\u001b[0m \u001b[38;5;28;01mexcept\u001b[39;00m (ProtocolError, \u001b[38;5;167;01mOSError\u001b[39;00m) \u001b[38;5;28;01mas\u001b[39;00m err:\n",
      "File \u001b[1;32m~\\Anaconda3\\lib\\site-packages\\urllib3\\connectionpool.py:799\u001b[0m, in \u001b[0;36mHTTPConnectionPool.urlopen\u001b[1;34m(self, method, url, body, headers, retries, redirect, assert_same_host, timeout, pool_timeout, release_conn, chunked, body_pos, **response_kw)\u001b[0m\n\u001b[0;32m    797\u001b[0m     e \u001b[38;5;241m=\u001b[39m ProtocolError(\u001b[38;5;124m\"\u001b[39m\u001b[38;5;124mConnection aborted.\u001b[39m\u001b[38;5;124m\"\u001b[39m, e)\n\u001b[1;32m--> 799\u001b[0m retries \u001b[38;5;241m=\u001b[39m \u001b[43mretries\u001b[49m\u001b[38;5;241;43m.\u001b[39;49m\u001b[43mincrement\u001b[49m\u001b[43m(\u001b[49m\n\u001b[0;32m    800\u001b[0m \u001b[43m    \u001b[49m\u001b[43mmethod\u001b[49m\u001b[43m,\u001b[49m\u001b[43m \u001b[49m\u001b[43murl\u001b[49m\u001b[43m,\u001b[49m\u001b[43m \u001b[49m\u001b[43merror\u001b[49m\u001b[38;5;241;43m=\u001b[39;49m\u001b[43me\u001b[49m\u001b[43m,\u001b[49m\u001b[43m \u001b[49m\u001b[43m_pool\u001b[49m\u001b[38;5;241;43m=\u001b[39;49m\u001b[38;5;28;43mself\u001b[39;49m\u001b[43m,\u001b[49m\u001b[43m \u001b[49m\u001b[43m_stacktrace\u001b[49m\u001b[38;5;241;43m=\u001b[39;49m\u001b[43msys\u001b[49m\u001b[38;5;241;43m.\u001b[39;49m\u001b[43mexc_info\u001b[49m\u001b[43m(\u001b[49m\u001b[43m)\u001b[49m\u001b[43m[\u001b[49m\u001b[38;5;241;43m2\u001b[39;49m\u001b[43m]\u001b[49m\n\u001b[0;32m    801\u001b[0m \u001b[43m\u001b[49m\u001b[43m)\u001b[49m\n\u001b[0;32m    802\u001b[0m retries\u001b[38;5;241m.\u001b[39msleep()\n",
      "File \u001b[1;32m~\\Anaconda3\\lib\\site-packages\\urllib3\\util\\retry.py:592\u001b[0m, in \u001b[0;36mRetry.increment\u001b[1;34m(self, method, url, response, error, _pool, _stacktrace)\u001b[0m\n\u001b[0;32m    591\u001b[0m \u001b[38;5;28;01mif\u001b[39;00m new_retry\u001b[38;5;241m.\u001b[39mis_exhausted():\n\u001b[1;32m--> 592\u001b[0m     \u001b[38;5;28;01mraise\u001b[39;00m MaxRetryError(_pool, url, error \u001b[38;5;129;01mor\u001b[39;00m ResponseError(cause))\n\u001b[0;32m    594\u001b[0m log\u001b[38;5;241m.\u001b[39mdebug(\u001b[38;5;124m\"\u001b[39m\u001b[38;5;124mIncremented Retry for (url=\u001b[39m\u001b[38;5;124m'\u001b[39m\u001b[38;5;132;01m%s\u001b[39;00m\u001b[38;5;124m'\u001b[39m\u001b[38;5;124m): \u001b[39m\u001b[38;5;132;01m%r\u001b[39;00m\u001b[38;5;124m\"\u001b[39m, url, new_retry)\n",
      "\u001b[1;31mMaxRetryError\u001b[0m: HTTPConnectionPool(host='0.0.0.0', port=8080): Max retries exceeded with url: /_alive_b3236f93-da64-4976-ba8e-a9c286fec5c6 (Caused by NewConnectionError('<urllib3.connection.HTTPConnection object at 0x000001BC5B4EAC40>: Failed to establish a new connection: [WinError 10049] Die angeforderte Adresse ist in diesem Kontext ungültig'))",
      "\nDuring handling of the above exception, another exception occurred:\n",
      "\u001b[1;31mConnectionError\u001b[0m                           Traceback (most recent call last)",
      "Cell \u001b[1;32mIn[1], line 32\u001b[0m\n\u001b[0;32m     29\u001b[0m     \u001b[38;5;28;01mreturn\u001b[39;00m fig\n\u001b[0;32m     31\u001b[0m \u001b[38;5;66;03m# Run Dash app in inline mode (for Jupyter Notebook)\u001b[39;00m\n\u001b[1;32m---> 32\u001b[0m \u001b[43mapp\u001b[49m\u001b[38;5;241;43m.\u001b[39;49m\u001b[43mrun\u001b[49m\u001b[43m(\u001b[49m\u001b[43mhost\u001b[49m\u001b[38;5;241;43m=\u001b[39;49m\u001b[38;5;124;43m\"\u001b[39;49m\u001b[38;5;124;43m0.0.0.0\u001b[39;49m\u001b[38;5;124;43m\"\u001b[39;49m\u001b[43m,\u001b[49m\u001b[43m \u001b[49m\u001b[43mport\u001b[49m\u001b[38;5;241;43m=\u001b[39;49m\u001b[38;5;241;43m8080\u001b[39;49m\u001b[43m)\u001b[49m\n",
      "File \u001b[1;32m~\\Anaconda3\\lib\\site-packages\\dash\\dash.py:2066\u001b[0m, in \u001b[0;36mDash.run\u001b[1;34m(self, host, port, proxy, debug, jupyter_mode, jupyter_width, jupyter_height, jupyter_server_url, dev_tools_ui, dev_tools_props_check, dev_tools_serve_dev_bundles, dev_tools_hot_reload, dev_tools_hot_reload_interval, dev_tools_hot_reload_watch_interval, dev_tools_hot_reload_max_retry, dev_tools_silence_routes_logging, dev_tools_prune_errors, **flask_run_options)\u001b[0m\n\u001b[0;32m   2063\u001b[0m             extra_files\u001b[38;5;241m.\u001b[39mappend(path)\n\u001b[0;32m   2065\u001b[0m \u001b[38;5;28;01mif\u001b[39;00m jupyter_dash\u001b[38;5;241m.\u001b[39mactive:\n\u001b[1;32m-> 2066\u001b[0m     \u001b[43mjupyter_dash\u001b[49m\u001b[38;5;241;43m.\u001b[39;49m\u001b[43mrun_app\u001b[49m\u001b[43m(\u001b[49m\n\u001b[0;32m   2067\u001b[0m \u001b[43m        \u001b[49m\u001b[38;5;28;43mself\u001b[39;49m\u001b[43m,\u001b[49m\n\u001b[0;32m   2068\u001b[0m \u001b[43m        \u001b[49m\u001b[43mmode\u001b[49m\u001b[38;5;241;43m=\u001b[39;49m\u001b[43mjupyter_mode\u001b[49m\u001b[43m,\u001b[49m\n\u001b[0;32m   2069\u001b[0m \u001b[43m        \u001b[49m\u001b[43mwidth\u001b[49m\u001b[38;5;241;43m=\u001b[39;49m\u001b[43mjupyter_width\u001b[49m\u001b[43m,\u001b[49m\n\u001b[0;32m   2070\u001b[0m \u001b[43m        \u001b[49m\u001b[43mheight\u001b[49m\u001b[38;5;241;43m=\u001b[39;49m\u001b[43mjupyter_height\u001b[49m\u001b[43m,\u001b[49m\n\u001b[0;32m   2071\u001b[0m \u001b[43m        \u001b[49m\u001b[43mhost\u001b[49m\u001b[38;5;241;43m=\u001b[39;49m\u001b[43mhost\u001b[49m\u001b[43m,\u001b[49m\n\u001b[0;32m   2072\u001b[0m \u001b[43m        \u001b[49m\u001b[43mport\u001b[49m\u001b[38;5;241;43m=\u001b[39;49m\u001b[43mport\u001b[49m\u001b[43m,\u001b[49m\n\u001b[0;32m   2073\u001b[0m \u001b[43m        \u001b[49m\u001b[43mserver_url\u001b[49m\u001b[38;5;241;43m=\u001b[39;49m\u001b[43mjupyter_server_url\u001b[49m\u001b[43m,\u001b[49m\n\u001b[0;32m   2074\u001b[0m \u001b[43m    \u001b[49m\u001b[43m)\u001b[49m\n\u001b[0;32m   2075\u001b[0m \u001b[38;5;28;01melse\u001b[39;00m:\n\u001b[0;32m   2076\u001b[0m     \u001b[38;5;28mself\u001b[39m\u001b[38;5;241m.\u001b[39mserver\u001b[38;5;241m.\u001b[39mrun(host\u001b[38;5;241m=\u001b[39mhost, port\u001b[38;5;241m=\u001b[39mport, debug\u001b[38;5;241m=\u001b[39mdebug, \u001b[38;5;241m*\u001b[39m\u001b[38;5;241m*\u001b[39mflask_run_options)\n",
      "File \u001b[1;32m~\\Anaconda3\\lib\\site-packages\\dash\\_jupyter.py:401\u001b[0m, in \u001b[0;36mJupyterDash.run_app\u001b[1;34m(self, app, mode, width, height, host, port, server_url)\u001b[0m\n\u001b[0;32m    399\u001b[0m     display(HTML(msg))\n\u001b[0;32m    400\u001b[0m \u001b[38;5;28;01melse\u001b[39;00m:\n\u001b[1;32m--> 401\u001b[0m     \u001b[38;5;28;01mraise\u001b[39;00m final_error\n",
      "File \u001b[1;32m~\\Anaconda3\\lib\\site-packages\\dash\\_jupyter.py:388\u001b[0m, in \u001b[0;36mJupyterDash.run_app\u001b[1;34m(self, app, mode, width, height, host, port, server_url)\u001b[0m\n\u001b[0;32m    385\u001b[0m         \u001b[38;5;28;01mraise\u001b[39;00m err\n\u001b[0;32m    387\u001b[0m \u001b[38;5;28;01mtry\u001b[39;00m:\n\u001b[1;32m--> 388\u001b[0m     \u001b[43mwait_for_app\u001b[49m\u001b[43m(\u001b[49m\u001b[43m)\u001b[49m\n\u001b[0;32m    390\u001b[0m     \u001b[38;5;28;01mif\u001b[39;00m \u001b[38;5;28mself\u001b[39m\u001b[38;5;241m.\u001b[39min_colab:\n\u001b[0;32m    391\u001b[0m         JupyterDash\u001b[38;5;241m.\u001b[39m_display_in_colab(dashboard_url, port, mode, width, height)\n",
      "File \u001b[1;32m~\\Anaconda3\\lib\\site-packages\\retrying.py:49\u001b[0m, in \u001b[0;36mretry.<locals>.wrap.<locals>.wrapped_f\u001b[1;34m(*args, **kw)\u001b[0m\n\u001b[0;32m     47\u001b[0m \u001b[38;5;129m@six\u001b[39m\u001b[38;5;241m.\u001b[39mwraps(f)\n\u001b[0;32m     48\u001b[0m \u001b[38;5;28;01mdef\u001b[39;00m \u001b[38;5;21mwrapped_f\u001b[39m(\u001b[38;5;241m*\u001b[39margs, \u001b[38;5;241m*\u001b[39m\u001b[38;5;241m*\u001b[39mkw):\n\u001b[1;32m---> 49\u001b[0m     \u001b[38;5;28;01mreturn\u001b[39;00m Retrying(\u001b[38;5;241m*\u001b[39mdargs, \u001b[38;5;241m*\u001b[39m\u001b[38;5;241m*\u001b[39mdkw)\u001b[38;5;241m.\u001b[39mcall(f, \u001b[38;5;241m*\u001b[39margs, \u001b[38;5;241m*\u001b[39m\u001b[38;5;241m*\u001b[39mkw)\n",
      "File \u001b[1;32m~\\Anaconda3\\lib\\site-packages\\retrying.py:212\u001b[0m, in \u001b[0;36mRetrying.call\u001b[1;34m(self, fn, *args, **kwargs)\u001b[0m\n\u001b[0;32m    209\u001b[0m \u001b[38;5;28;01mif\u001b[39;00m \u001b[38;5;28mself\u001b[39m\u001b[38;5;241m.\u001b[39mstop(attempt_number, delay_since_first_attempt_ms):\n\u001b[0;32m    210\u001b[0m     \u001b[38;5;28;01mif\u001b[39;00m \u001b[38;5;129;01mnot\u001b[39;00m \u001b[38;5;28mself\u001b[39m\u001b[38;5;241m.\u001b[39m_wrap_exception \u001b[38;5;129;01mand\u001b[39;00m attempt\u001b[38;5;241m.\u001b[39mhas_exception:\n\u001b[0;32m    211\u001b[0m         \u001b[38;5;66;03m# get() on an attempt with an exception should cause it to be raised, but raise just in case\u001b[39;00m\n\u001b[1;32m--> 212\u001b[0m         \u001b[38;5;28;01mraise\u001b[39;00m \u001b[43mattempt\u001b[49m\u001b[38;5;241;43m.\u001b[39;49m\u001b[43mget\u001b[49m\u001b[43m(\u001b[49m\u001b[43m)\u001b[49m\n\u001b[0;32m    213\u001b[0m     \u001b[38;5;28;01melse\u001b[39;00m:\n\u001b[0;32m    214\u001b[0m         \u001b[38;5;28;01mraise\u001b[39;00m RetryError(attempt)\n",
      "File \u001b[1;32m~\\Anaconda3\\lib\\site-packages\\retrying.py:247\u001b[0m, in \u001b[0;36mAttempt.get\u001b[1;34m(self, wrap_exception)\u001b[0m\n\u001b[0;32m    245\u001b[0m         \u001b[38;5;28;01mraise\u001b[39;00m RetryError(\u001b[38;5;28mself\u001b[39m)\n\u001b[0;32m    246\u001b[0m     \u001b[38;5;28;01melse\u001b[39;00m:\n\u001b[1;32m--> 247\u001b[0m         \u001b[43msix\u001b[49m\u001b[38;5;241;43m.\u001b[39;49m\u001b[43mreraise\u001b[49m\u001b[43m(\u001b[49m\u001b[38;5;28;43mself\u001b[39;49m\u001b[38;5;241;43m.\u001b[39;49m\u001b[43mvalue\u001b[49m\u001b[43m[\u001b[49m\u001b[38;5;241;43m0\u001b[39;49m\u001b[43m]\u001b[49m\u001b[43m,\u001b[49m\u001b[43m \u001b[49m\u001b[38;5;28;43mself\u001b[39;49m\u001b[38;5;241;43m.\u001b[39;49m\u001b[43mvalue\u001b[49m\u001b[43m[\u001b[49m\u001b[38;5;241;43m1\u001b[39;49m\u001b[43m]\u001b[49m\u001b[43m,\u001b[49m\u001b[43m \u001b[49m\u001b[38;5;28;43mself\u001b[39;49m\u001b[38;5;241;43m.\u001b[39;49m\u001b[43mvalue\u001b[49m\u001b[43m[\u001b[49m\u001b[38;5;241;43m2\u001b[39;49m\u001b[43m]\u001b[49m\u001b[43m)\u001b[49m\n\u001b[0;32m    248\u001b[0m \u001b[38;5;28;01melse\u001b[39;00m:\n\u001b[0;32m    249\u001b[0m     \u001b[38;5;28;01mreturn\u001b[39;00m \u001b[38;5;28mself\u001b[39m\u001b[38;5;241m.\u001b[39mvalue\n",
      "File \u001b[1;32m~\\Anaconda3\\lib\\site-packages\\six.py:719\u001b[0m, in \u001b[0;36mreraise\u001b[1;34m(tp, value, tb)\u001b[0m\n\u001b[0;32m    717\u001b[0m     \u001b[38;5;28;01mif\u001b[39;00m value\u001b[38;5;241m.\u001b[39m__traceback__ \u001b[38;5;129;01mis\u001b[39;00m \u001b[38;5;129;01mnot\u001b[39;00m tb:\n\u001b[0;32m    718\u001b[0m         \u001b[38;5;28;01mraise\u001b[39;00m value\u001b[38;5;241m.\u001b[39mwith_traceback(tb)\n\u001b[1;32m--> 719\u001b[0m     \u001b[38;5;28;01mraise\u001b[39;00m value\n\u001b[0;32m    720\u001b[0m \u001b[38;5;28;01mfinally\u001b[39;00m:\n\u001b[0;32m    721\u001b[0m     value \u001b[38;5;241m=\u001b[39m \u001b[38;5;28;01mNone\u001b[39;00m\n",
      "File \u001b[1;32m~\\Anaconda3\\lib\\site-packages\\retrying.py:200\u001b[0m, in \u001b[0;36mRetrying.call\u001b[1;34m(self, fn, *args, **kwargs)\u001b[0m\n\u001b[0;32m    198\u001b[0m \u001b[38;5;28;01mwhile\u001b[39;00m \u001b[38;5;28;01mTrue\u001b[39;00m:\n\u001b[0;32m    199\u001b[0m     \u001b[38;5;28;01mtry\u001b[39;00m:\n\u001b[1;32m--> 200\u001b[0m         attempt \u001b[38;5;241m=\u001b[39m Attempt(fn(\u001b[38;5;241m*\u001b[39margs, \u001b[38;5;241m*\u001b[39m\u001b[38;5;241m*\u001b[39mkwargs), attempt_number, \u001b[38;5;28;01mFalse\u001b[39;00m)\n\u001b[0;32m    201\u001b[0m     \u001b[38;5;28;01mexcept\u001b[39;00m:\n\u001b[0;32m    202\u001b[0m         tb \u001b[38;5;241m=\u001b[39m sys\u001b[38;5;241m.\u001b[39mexc_info()\n",
      "File \u001b[1;32m~\\Anaconda3\\lib\\site-packages\\dash\\_jupyter.py:385\u001b[0m, in \u001b[0;36mJupyterDash.run_app.<locals>.wait_for_app\u001b[1;34m()\u001b[0m\n\u001b[0;32m    383\u001b[0m \u001b[38;5;28;01mexcept\u001b[39;00m requests\u001b[38;5;241m.\u001b[39mConnectionError \u001b[38;5;28;01mas\u001b[39;00m err:\n\u001b[0;32m    384\u001b[0m     _get_error()\n\u001b[1;32m--> 385\u001b[0m     \u001b[38;5;28;01mraise\u001b[39;00m err\n",
      "File \u001b[1;32m~\\Anaconda3\\lib\\site-packages\\dash\\_jupyter.py:372\u001b[0m, in \u001b[0;36mJupyterDash.run_app.<locals>.wait_for_app\u001b[1;34m()\u001b[0m\n\u001b[0;32m    370\u001b[0m _get_error()\n\u001b[0;32m    371\u001b[0m \u001b[38;5;28;01mtry\u001b[39;00m:\n\u001b[1;32m--> 372\u001b[0m     req \u001b[38;5;241m=\u001b[39m \u001b[43mrequests\u001b[49m\u001b[38;5;241;43m.\u001b[39;49m\u001b[43mget\u001b[49m\u001b[43m(\u001b[49m\u001b[43malive_url\u001b[49m\u001b[43m)\u001b[49m\n\u001b[0;32m    373\u001b[0m     res \u001b[38;5;241m=\u001b[39m req\u001b[38;5;241m.\u001b[39mcontent\u001b[38;5;241m.\u001b[39mdecode()\n\u001b[0;32m    374\u001b[0m     \u001b[38;5;28;01mif\u001b[39;00m req\u001b[38;5;241m.\u001b[39mstatus_code \u001b[38;5;241m!=\u001b[39m \u001b[38;5;241m200\u001b[39m:\n",
      "File \u001b[1;32m~\\Anaconda3\\lib\\site-packages\\requests\\api.py:73\u001b[0m, in \u001b[0;36mget\u001b[1;34m(url, params, **kwargs)\u001b[0m\n\u001b[0;32m     62\u001b[0m \u001b[38;5;28;01mdef\u001b[39;00m \u001b[38;5;21mget\u001b[39m(url, params\u001b[38;5;241m=\u001b[39m\u001b[38;5;28;01mNone\u001b[39;00m, \u001b[38;5;241m*\u001b[39m\u001b[38;5;241m*\u001b[39mkwargs):\n\u001b[0;32m     63\u001b[0m \u001b[38;5;250m    \u001b[39m\u001b[38;5;124mr\u001b[39m\u001b[38;5;124;03m\"\"\"Sends a GET request.\u001b[39;00m\n\u001b[0;32m     64\u001b[0m \n\u001b[0;32m     65\u001b[0m \u001b[38;5;124;03m    :param url: URL for the new :class:`Request` object.\u001b[39;00m\n\u001b[1;32m   (...)\u001b[0m\n\u001b[0;32m     70\u001b[0m \u001b[38;5;124;03m    :rtype: requests.Response\u001b[39;00m\n\u001b[0;32m     71\u001b[0m \u001b[38;5;124;03m    \"\"\"\u001b[39;00m\n\u001b[1;32m---> 73\u001b[0m     \u001b[38;5;28;01mreturn\u001b[39;00m request(\u001b[38;5;124m\"\u001b[39m\u001b[38;5;124mget\u001b[39m\u001b[38;5;124m\"\u001b[39m, url, params\u001b[38;5;241m=\u001b[39mparams, \u001b[38;5;241m*\u001b[39m\u001b[38;5;241m*\u001b[39mkwargs)\n",
      "File \u001b[1;32m~\\Anaconda3\\lib\\site-packages\\requests\\api.py:59\u001b[0m, in \u001b[0;36mrequest\u001b[1;34m(method, url, **kwargs)\u001b[0m\n\u001b[0;32m     55\u001b[0m \u001b[38;5;66;03m# By using the 'with' statement we are sure the session is closed, thus we\u001b[39;00m\n\u001b[0;32m     56\u001b[0m \u001b[38;5;66;03m# avoid leaving sockets open which can trigger a ResourceWarning in some\u001b[39;00m\n\u001b[0;32m     57\u001b[0m \u001b[38;5;66;03m# cases, and look like a memory leak in others.\u001b[39;00m\n\u001b[0;32m     58\u001b[0m \u001b[38;5;28;01mwith\u001b[39;00m sessions\u001b[38;5;241m.\u001b[39mSession() \u001b[38;5;28;01mas\u001b[39;00m session:\n\u001b[1;32m---> 59\u001b[0m     \u001b[38;5;28;01mreturn\u001b[39;00m session\u001b[38;5;241m.\u001b[39mrequest(method\u001b[38;5;241m=\u001b[39mmethod, url\u001b[38;5;241m=\u001b[39murl, \u001b[38;5;241m*\u001b[39m\u001b[38;5;241m*\u001b[39mkwargs)\n",
      "File \u001b[1;32m~\\Anaconda3\\lib\\site-packages\\requests\\sessions.py:589\u001b[0m, in \u001b[0;36mSession.request\u001b[1;34m(self, method, url, params, data, headers, cookies, files, auth, timeout, allow_redirects, proxies, hooks, stream, verify, cert, json)\u001b[0m\n\u001b[0;32m    584\u001b[0m send_kwargs \u001b[38;5;241m=\u001b[39m {\n\u001b[0;32m    585\u001b[0m     \u001b[38;5;124m\"\u001b[39m\u001b[38;5;124mtimeout\u001b[39m\u001b[38;5;124m\"\u001b[39m: timeout,\n\u001b[0;32m    586\u001b[0m     \u001b[38;5;124m\"\u001b[39m\u001b[38;5;124mallow_redirects\u001b[39m\u001b[38;5;124m\"\u001b[39m: allow_redirects,\n\u001b[0;32m    587\u001b[0m }\n\u001b[0;32m    588\u001b[0m send_kwargs\u001b[38;5;241m.\u001b[39mupdate(settings)\n\u001b[1;32m--> 589\u001b[0m resp \u001b[38;5;241m=\u001b[39m \u001b[38;5;28mself\u001b[39m\u001b[38;5;241m.\u001b[39msend(prep, \u001b[38;5;241m*\u001b[39m\u001b[38;5;241m*\u001b[39msend_kwargs)\n\u001b[0;32m    591\u001b[0m \u001b[38;5;28;01mreturn\u001b[39;00m resp\n",
      "File \u001b[1;32m~\\Anaconda3\\lib\\site-packages\\requests\\sessions.py:703\u001b[0m, in \u001b[0;36mSession.send\u001b[1;34m(self, request, **kwargs)\u001b[0m\n\u001b[0;32m    700\u001b[0m start \u001b[38;5;241m=\u001b[39m preferred_clock()\n\u001b[0;32m    702\u001b[0m \u001b[38;5;66;03m# Send the request\u001b[39;00m\n\u001b[1;32m--> 703\u001b[0m r \u001b[38;5;241m=\u001b[39m adapter\u001b[38;5;241m.\u001b[39msend(request, \u001b[38;5;241m*\u001b[39m\u001b[38;5;241m*\u001b[39mkwargs)\n\u001b[0;32m    705\u001b[0m \u001b[38;5;66;03m# Total elapsed time of the request (approximately)\u001b[39;00m\n\u001b[0;32m    706\u001b[0m elapsed \u001b[38;5;241m=\u001b[39m preferred_clock() \u001b[38;5;241m-\u001b[39m start\n",
      "File \u001b[1;32m~\\Anaconda3\\lib\\site-packages\\requests\\adapters.py:519\u001b[0m, in \u001b[0;36mHTTPAdapter.send\u001b[1;34m(self, request, stream, timeout, verify, cert, proxies)\u001b[0m\n\u001b[0;32m    515\u001b[0m     \u001b[38;5;28;01mif\u001b[39;00m \u001b[38;5;28misinstance\u001b[39m(e\u001b[38;5;241m.\u001b[39mreason, _SSLError):\n\u001b[0;32m    516\u001b[0m         \u001b[38;5;66;03m# This branch is for urllib3 v1.22 and later.\u001b[39;00m\n\u001b[0;32m    517\u001b[0m         \u001b[38;5;28;01mraise\u001b[39;00m SSLError(e, request\u001b[38;5;241m=\u001b[39mrequest)\n\u001b[1;32m--> 519\u001b[0m     \u001b[38;5;28;01mraise\u001b[39;00m \u001b[38;5;167;01mConnectionError\u001b[39;00m(e, request\u001b[38;5;241m=\u001b[39mrequest)\n\u001b[0;32m    521\u001b[0m \u001b[38;5;28;01mexcept\u001b[39;00m ClosedPoolError \u001b[38;5;28;01mas\u001b[39;00m e:\n\u001b[0;32m    522\u001b[0m     \u001b[38;5;28;01mraise\u001b[39;00m \u001b[38;5;167;01mConnectionError\u001b[39;00m(e, request\u001b[38;5;241m=\u001b[39mrequest)\n",
      "\u001b[1;31mConnectionError\u001b[0m: HTTPConnectionPool(host='0.0.0.0', port=8080): Max retries exceeded with url: /_alive_b3236f93-da64-4976-ba8e-a9c286fec5c6 (Caused by NewConnectionError('<urllib3.connection.HTTPConnection object at 0x000001BC5B4EAC40>: Failed to establish a new connection: [WinError 10049] Die angeforderte Adresse ist in diesem Kontext ungültig'))"
     ]
    }
   ],
   "source": [
    "import ipywidgets as widgets\n",
    "from dash import Dash, dcc, html, Input, Output\n",
    "import plotly.express as px\n",
    "import pandas as pd\n",
    "\n",
    "# Sample Data\n",
    "df = px.data.iris()\n",
    "\n",
    "# Dash App inside Jupyter\n",
    "app = Dash(__name__)\n",
    "\n",
    "app.layout = html.Div([\n",
    "    html.H1(\"Iris Dataset Visualization\"),\n",
    "    dcc.Dropdown(\n",
    "        id='feature-dropdown',\n",
    "        options=[{'label': col, 'value': col} for col in df.columns if df[col].dtype != 'object'],\n",
    "        value='sepal_length',\n",
    "        clearable=False\n",
    "    ),\n",
    "    dcc.Graph(id='scatter-plot')\n",
    "])\n",
    "\n",
    "@app.callback(\n",
    "    Output('scatter-plot', 'figure'),\n",
    "    Input('feature-dropdown', 'value')\n",
    ")\n",
    "def update_chart(feature):\n",
    "    fig = px.histogram(df, x=feature, nbins=20, title=f\"Distribution of {feature}\")\n",
    "    return fig\n",
    "\n",
    "# Run Dash app in inline mode (for Jupyter Notebook)\n",
    "app.run(mode=\"jupyterlab\", host=\"0.0.0.0\", port=8080)"
   ]
  }
 ],
 "metadata": {
  "kernelspec": {
   "display_name": "Python 3 (ipykernel)",
   "language": "python",
   "name": "python3"
  },
  "language_info": {
   "codemirror_mode": {
    "name": "ipython",
    "version": 3
   },
   "file_extension": ".py",
   "mimetype": "text/x-python",
   "name": "python",
   "nbconvert_exporter": "python",
   "pygments_lexer": "ipython3",
   "version": "3.9.18"
  }
 },
 "nbformat": 4,
 "nbformat_minor": 5
}
